2022-11-19 21:19:49.866 WARNING (SyncWorker_0) [homeassistant.loader] We found a custom integration unifigateway which has not been tested by Home Assistant. This component might cause stability problems, be sure to disable it if you experience issues with Home Assistant
2022-11-19 21:19:49.867 WARNING (SyncWorker_0) [homeassistant.loader] We found a custom integration xiaomi_cloud_map_extractor which has not been tested by Home Assistant. This component might cause stability problems, be sure to disable it if you experience issues with Home Assistant
2022-11-19 21:19:49.867 WARNING (SyncWorker_0) [homeassistant.loader] We found a custom integration smartthinq_sensors which has not been tested by Home Assistant. This component might cause stability problems, be sure to disable it if you experience issues with Home Assistant
2022-11-19 21:19:49.867 WARNING (SyncWorker_0) [homeassistant.loader] We found a custom integration nodered which has not been tested by Home Assistant. This component might cause stability problems, be sure to disable it if you experience issues with Home Assistant
2022-11-19 21:19:49.867 WARNING (SyncWorker_0) [homeassistant.loader] We found a custom integration hacs which has not been tested by Home Assistant. This component might cause stability problems, be sure to disable it if you experience issues with Home Assistant
2022-11-19 21:19:49.868 WARNING (SyncWorker_0) [homeassistant.loader] We found a custom integration xiaomi_miot which has not been tested by Home Assistant. This component might cause stability problems, be sure to disable it if you experience issues with Home Assistant
2022-11-19 21:19:49.868 WARNING (SyncWorker_0) [homeassistant.loader] We found a custom integration tesla_custom which has not been tested by Home Assistant. This component might cause stability problems, be sure to disable it if you experience issues with Home Assistant
2022-11-19 21:19:50.923 WARNING (SyncWorker_2) [homeassistant.util.yaml.loader] YAML file /config/includes/main.yaml contains duplicate key "type". Check lines 788 and 789
2022-11-19 21:19:53.851 WARNING (MainThread) [homeassistant.config_entries] Config entry 'Roku-Office' for roku integration not ready yet: Invalid response from API: Error occurred while communicating with device; Retrying in background
2022-11-19 21:19:54.481 WARNING (MainThread) [homeassistant.components.unifiprotect.migrate] Failed to migate 1 reboot buttons
2022-11-19 21:19:54.582 WARNING (MainThread) [homeassistant.components.unifiprotect.migrate] Failed to migrate 24 entities
2022-11-19 21:19:54.993 WARNING (MainThread) [custom_components.xiaomi_miot] None device in xiaomi cloud: newlon@outlook.com
2022-11-19 21:19:57.098 WARNING (MainThread) [aioesphomeapi.reconnect_logic] Can't connect to ESPHome API for powermeter-18c @ 10.1.30.71: Error connecting to ('10.1.30.71', 6053): [Errno 113] Connect call failed ('10.1.30.71', 6053)
2022-11-19 21:20:03.200 WARNING (MainThread) [zigpy_znp.zigbee.application] Your network is using the insecure Zigbee2MQTT network key!
2022-11-19 21:20:04.471 WARNING (MainThread) [homeassistant.components.sonos.switch] Migration of Speech Enhancement switches on Living Room failed, manual cleanup required: ['switch.sonos_living_room_speech_enhancement', 'switch.sonos_living_room_speech_enhancement_2']
2022-11-19 21:21:09.363 WARNING (MainThread) [aiounifi.models.message] Unsupported message key setting:sync
2022-11-19 21:21:09.364 WARNING (MainThread) [aiounifi.models.message] Unsupported message {'meta': {'rc': 'ok', 'message': 'setting:sync'}, 'data': {'_id': '5e43108f1c7bfa025b1e8c6a', 'key': 'ips', 'site_id': '5e42db1c7a5dae02b933554d', 'ips_mode': 'ips', 'utm_token': '25eca604cdb690e65e93fefef7f41aa3467510da449d76e8f19badbf0c1128455', 'last_alert_id': '1822066555-2022-11-19T12:47:53.932625-0500', 'enabled_categories': ['botcc', 'emerging-worm', 'emerging-malware', 'emerging-mobile', 'emerging-trojan', 'emerging-p2p', 'tor', 'emerging-exploit', 'emerging-shellcode', 'emerging-dos', 'emerging-attackresponse', 'emerging-scan', 'emerging-rpc', 'emerging-activex', 'emerging-dns', 'emerging-games', 'emerging-sql', 'emerging-useragent', 'emerging-webapps', 'emerging-webclient', 'emerging-webserver', 'ciarmy', 'compromised', 'dshield', 'emerging-ftp', 'emerging-icmp', 'emerging-imap', 'emerging-misc', 'emerging-netbios', 'emerging-pop3', 'emerging-smtp', 'emerging-snmp', 'emerging-telnet', 'emerging-tftp', 'emerging-voip'], 'restrict_ip_addresses': True, 'restrict_tor': True, 'suppression': {'alerts': [], 'whitelist': []}, 'endpoint_scanning': False, 'honeypot_enabled': True, 'last_nmap_id': '580600963-Mon Dec 27 09:52:41 2021', 'dns_filtering': True, 'dns_filters': [{'allowed_sites': [], 'blocked_sites': [], 'blocked_tld': [], 'description': '', 'filter': 'none', 'version': 'v4', 'network_id': '6266a4044ded3805c74272ad', 'name': ''}, {'allowed_sites': [], 'blocked_sites': [], 'blocked_tld': [], 'description': '', 'filter': 'none', 'version': 'v4', 'network_id': '62643910d2a98c05ccc7dd0d', 'name': ''}, {'allowed_sites': [], 'blocked_sites': [], 'blocked_tld': [], 'description': '', 'filter': 'none', 'version': 'v4', 'network_id': '62643d65d2a98c05ccc7de24', 'name': ''}, {'allowed_sites': [], 'blocked_sites': [], 'blocked_tld': [], 'description': '', 'filter': 'none', 'version': 'v4', 'network_id': '5e42db1f7a5dae02b933555d', 'name': ''}, {'allowed_sites': [], 'blocked_sites': [], 'blocked_tld': [], 'description': '', 'filter': 'none', 'version': 'v4', 'network_id': '5f70f18b72dbef4dca8df269', 'name': ''}], 'honeypot': []}}
2022-11-19 21:21:09.384 WARNING (MainThread) [aiounifi.models.message] Unsupported message key setting:sync
2022-11-19 21:21:09.385 WARNING (MainThread) [aiounifi.models.message] Unsupported message {'meta': {'rc': 'ok', 'message': 'setting:sync'}, 'data': {'_id': '5e42db1f7a5dae02b9335559', 'site_id': '5e42db1c7a5dae02b933554d', 'key': 'usg', 'ftp_module': True, 'gre_module': True, 'h323_module': True, 'pptp_module': True, 'sip_module': True, 'tftp_module': True, 'broadcast_ping': False, 'receive_redirects': False, 'send_redirects': True, 'syn_cookies': True, 'offload_accounting': True, 'offload_sch': True, 'offload_l2_blocking': True, 'upnp_enabled': True, 'upnp_nat_pmp_enabled': True, 'upnp_secure_mode': True, 'mss_clamp': 'auto', 'geo_ip_filtering_enabled': True, 'geo_ip_filtering_block': 'allow', 'geo_ip_filtering_countries': 'US', 'geo_ip_filtering_traffic_direction': 'ingress', 'upnp_wan_interface': 'WAN', 'icmp_timeout': 30, 'other_timeout': 600, 'tcp_close_timeout': 10, 'tcp_close_wait_timeout': 60, 'tcp_established_timeout': 7440, 'tcp_fin_wait_timeout': 120, 'tcp_last_ack_timeout': 30, 'tcp_syn_recv_timeout': 60, 'tcp_syn_sent_timeout': 120, 'tcp_time_wait_timeout': 120, 'udp_other_timeout': 30, 'udp_stream_timeout': 180, 'timeout_setting_preference': 'manual', 'mss_clamp_mss': 1452, 'arp_cache_timeout': 'normal', 'arp_cache_base_reachable': 30, 'echo_server': 'ping.ubnt.com', 'firewall_wan_default_log': True, 'dhcp_relay_agents_packets': '', 'dhcp_relay_port': '', 'dhcp_relay_hop_count': '', 'firewall_lan_default_log': True, 'firewall_guest_default_log': False}}
2022-11-19 21:22:52.004 INFO (MainThread) [backoff] Backing off async_request(...) for 0.6s (tesla_wall_connector.exceptions.WallConnectorConnectionTimeoutError: Timeout while connecting to Wall Connector at 10.1.20.4)
2022-11-19 21:22:53.627 INFO (MainThread) [backoff] Backing off async_request(...) for 1.1s (tesla_wall_connector.exceptions.WallConnectorConnectionTimeoutError: Timeout while connecting to Wall Connector at 10.1.20.4)
2022-11-19 21:22:55.723 ERROR (MainThread) [backoff] Giving up async_request(...) after 3 tries (tesla_wall_connector.exceptions.WallConnectorConnectionTimeoutError: Timeout while connecting to Wall Connector at 10.1.20.4)
2022-11-19 21:22:55.724 ERROR (MainThread) [homeassistant.components.tesla_wall_connector] Error fetching tesla-wallconnector data: Could not fetch data from Tesla WallConnector at 10.1.20.4: Timeout
2022-11-19 21:23:26.093 INFO (MainThread) [backoff] Backing off async_request(...) for 0.7s (tesla_wall_connector.exceptions.WallConnectorConnectionTimeoutError: Timeout while connecting to Wall Connector at 10.1.20.4)
2022-11-19 21:25:57.056 INFO (MainThread) [backoff] Backing off async_request(...) for 0.4s (tesla_wall_connector.exceptions.WallConnectorConnectionTimeoutError: Timeout while connecting to Wall Connector at 10.1.20.4)
2022-11-19 21:25:58.500 INFO (MainThread) [backoff] Backing off async_request(...) for 1.4s (tesla_wall_connector.exceptions.WallConnectorConnectionTimeoutError: Timeout while connecting to Wall Connector at 10.1.20.4)
2022-11-19 21:28:00.001 INFO (MainThread) [backoff] Backing off async_request(...) for 0.1s (tesla_wall_connector.exceptions.WallConnectorConnectionTimeoutError: Timeout while connecting to Wall Connector at 10.1.20.4)
2022-11-19 21:30:39.209 ERROR (SyncWorker_10) [homeassistant.util.yaml.loader] mapping values are not allowed here
  in "/config/includes/automations.yaml", line 51, column 29
2022-11-19 21:30:39.210 ERROR (MainThread) [homeassistant.components.homeassistant] The system cannot restart because the configuration is not valid: Error loading /config/configuration.yaml: mapping values are not allowed here
  in "/config/includes/automations.yaml", line 51, column 29
2022-11-19 21:30:39.212 ERROR (MainThread) [homeassistant.components.websocket_api.http.connection] [22871377139968] The system cannot restart because the configuration is not valid: Error loading /config/configuration.yaml: mapping values are not allowed here
  in "/config/includes/automations.yaml", line 51, column 29
Traceback (most recent call last):
  File "/usr/src/homeassistant/homeassistant/components/websocket_api/commands.py", line 200, in handle_call_service
    await hass.services.async_call(
  File "/usr/src/homeassistant/homeassistant/core.py", line 1744, in async_call
    task.result()
  File "/usr/src/homeassistant/homeassistant/core.py", line 1781, in _execute_service
    await cast(Callable[[ServiceCall], Awaitable[None]], handler.job.target)(
  File "/usr/src/homeassistant/homeassistant/helpers/service.py", line 748, in admin_handler
    await result
  File "/usr/src/homeassistant/homeassistant/components/homeassistant/__init__.py", line 174, in async_handle_core_service
    raise HomeAssistantError(
homeassistant.exceptions.HomeAssistantError: The system cannot restart because the configuration is not valid: Error loading /config/configuration.yaml: mapping values are not allowed here
  in "/config/includes/automations.yaml", line 51, column 29
