2022-11-19 21:09:49.618 WARNING (SyncWorker_0) [homeassistant.loader] We found a custom integration unifigateway which has not been tested by Home Assistant. This component might cause stability problems, be sure to disable it if you experience issues with Home Assistant
2022-11-19 21:09:49.619 WARNING (SyncWorker_0) [homeassistant.loader] We found a custom integration xiaomi_cloud_map_extractor which has not been tested by Home Assistant. This component might cause stability problems, be sure to disable it if you experience issues with Home Assistant
2022-11-19 21:09:49.619 WARNING (SyncWorker_0) [homeassistant.loader] We found a custom integration smartthinq_sensors which has not been tested by Home Assistant. This component might cause stability problems, be sure to disable it if you experience issues with Home Assistant
2022-11-19 21:09:49.620 WARNING (SyncWorker_0) [homeassistant.loader] We found a custom integration nodered which has not been tested by Home Assistant. This component might cause stability problems, be sure to disable it if you experience issues with Home Assistant
2022-11-19 21:09:49.620 WARNING (SyncWorker_0) [homeassistant.loader] We found a custom integration hacs which has not been tested by Home Assistant. This component might cause stability problems, be sure to disable it if you experience issues with Home Assistant
2022-11-19 21:09:49.620 WARNING (SyncWorker_0) [homeassistant.loader] We found a custom integration xiaomi_miot which has not been tested by Home Assistant. This component might cause stability problems, be sure to disable it if you experience issues with Home Assistant
2022-11-19 21:09:49.620 WARNING (SyncWorker_0) [homeassistant.loader] We found a custom integration tesla_custom which has not been tested by Home Assistant. This component might cause stability problems, be sure to disable it if you experience issues with Home Assistant
2022-11-19 21:09:50.762 WARNING (SyncWorker_2) [homeassistant.util.yaml.loader] YAML file /config/includes/main.yaml contains duplicate key "type". Check lines 788 and 789
2022-11-19 21:09:53.112 WARNING (MainThread) [homeassistant.components.unifiprotect.migrate] Failed to migate 1 reboot buttons
2022-11-19 21:09:53.392 WARNING (MainThread) [homeassistant.components.unifiprotect.migrate] Failed to migrate 24 entities
2022-11-19 21:09:54.747 WARNING (MainThread) [custom_components.xiaomi_miot] None device in xiaomi cloud: newlon@outlook.com
2022-11-19 21:09:55.352 WARNING (MainThread) [homeassistant.config_entries] Config entry 'Roku-Office' for roku integration not ready yet: Invalid response from API: Error occurred while communicating with device; Retrying in background
2022-11-19 21:09:56.778 WARNING (MainThread) [aioesphomeapi.reconnect_logic] Can't connect to ESPHome API for powermeter-18c @ 10.1.30.71: Error connecting to ('10.1.30.71', 6053): [Errno 113] Connect call failed ('10.1.30.71', 6053)
2022-11-19 21:10:03.261 WARNING (MainThread) [zigpy_znp.zigbee.application] Your network is using the insecure Zigbee2MQTT network key!
2022-11-19 21:10:04.495 WARNING (MainThread) [homeassistant.components.sonos.switch] Migration of Speech Enhancement switches on Living Room failed, manual cleanup required: ['switch.sonos_living_room_speech_enhancement', 'switch.sonos_living_room_speech_enhancement_2']
2022-11-19 21:10:55.923 ERROR (MainThread) [homeassistant.components.shell_command] Error running command: `bin/bash pushupdates.sh`, return code: 127
NoneType: None
2022-11-19 21:11:54.312 INFO (MainThread) [backoff] Backing off async_request(...) for 0.4s (tesla_wall_connector.exceptions.WallConnectorConnectionTimeoutError: Timeout while connecting to Wall Connector at 10.1.20.4)
2022-11-19 21:14:25.002 INFO (MainThread) [backoff] Backing off async_request(...) for 0.8s (tesla_wall_connector.exceptions.WallConnectorConnectionTimeoutError: Timeout while connecting to Wall Connector at 10.1.20.4)
2022-11-19 21:16:26.057 INFO (MainThread) [backoff] Backing off async_request(...) for 0.5s (tesla_wall_connector.exceptions.WallConnectorConnectionTimeoutError: Timeout while connecting to Wall Connector at 10.1.20.4)
2022-11-19 21:17:11.479 WARNING (MainThread) [aiounifi.models.message] Unsupported message key setting:sync
2022-11-19 21:17:11.481 WARNING (MainThread) [aiounifi.models.message] Unsupported message {'meta': {'rc': 'ok', 'message': 'setting:sync'}, 'data': {'_id': '5e42db1f7a5dae02b9335559', 'site_id': '5e42db1c7a5dae02b933554d', 'key': 'usg', 'ftp_module': True, 'gre_module': True, 'h323_module': True, 'pptp_module': True, 'sip_module': True, 'tftp_module': True, 'broadcast_ping': False, 'receive_redirects': False, 'send_redirects': True, 'syn_cookies': True, 'offload_accounting': True, 'offload_sch': True, 'offload_l2_blocking': True, 'upnp_enabled': True, 'upnp_nat_pmp_enabled': True, 'upnp_secure_mode': True, 'mss_clamp': 'auto', 'geo_ip_filtering_enabled': False, 'geo_ip_filtering_block': 'block', 'geo_ip_filtering_countries': '', 'geo_ip_filtering_traffic_direction': 'both', 'upnp_wan_interface': 'WAN', 'icmp_timeout': 30, 'other_timeout': 600, 'tcp_close_timeout': 10, 'tcp_close_wait_timeout': 60, 'tcp_established_timeout': 7440, 'tcp_fin_wait_timeout': 120, 'tcp_last_ack_timeout': 30, 'tcp_syn_recv_timeout': 60, 'tcp_syn_sent_timeout': 120, 'tcp_time_wait_timeout': 120, 'udp_other_timeout': 30, 'udp_stream_timeout': 180, 'timeout_setting_preference': 'manual', 'mss_clamp_mss': 1452, 'arp_cache_timeout': 'normal', 'arp_cache_base_reachable': 30, 'echo_server': 'ping.ubnt.com', 'firewall_wan_default_log': True, 'dhcp_relay_agents_packets': '', 'dhcp_relay_port': '', 'dhcp_relay_hop_count': '', 'firewall_lan_default_log': True, 'firewall_guest_default_log': False}}
2022-11-19 21:17:11.508 WARNING (MainThread) [aiounifi.models.message] Unsupported message key setting:sync
2022-11-19 21:17:11.508 WARNING (MainThread) [aiounifi.models.message] Unsupported message {'meta': {'rc': 'ok', 'message': 'setting:sync'}, 'data': {'_id': '5e43108f1c7bfa025b1e8c6a', 'key': 'ips', 'site_id': '5e42db1c7a5dae02b933554d', 'ips_mode': 'disabled', 'utm_token': '25eca604cdb690e65e93fefef7f41aa3467510da449d76e8f19badbf0c1128455', 'last_alert_id': '1822066555-2022-11-19T12:47:53.932625-0500', 'enabled_categories': [], 'restrict_ip_addresses': False, 'restrict_tor': False, 'suppression': {'alerts': [], 'whitelist': []}, 'endpoint_scanning': False, 'honeypot_enabled': True, 'last_nmap_id': '580600963-Mon Dec 27 09:52:41 2021', 'dns_filtering': True, 'dns_filters': [{'allowed_sites': [], 'blocked_sites': [], 'blocked_tld': [], 'description': '', 'filter': 'none', 'version': 'v4', 'network_id': '6266a4044ded3805c74272ad', 'name': ''}, {'allowed_sites': [], 'blocked_sites': [], 'blocked_tld': [], 'description': '', 'filter': 'none', 'version': 'v4', 'network_id': '62643910d2a98c05ccc7dd0d', 'name': ''}, {'allowed_sites': [], 'blocked_sites': [], 'blocked_tld': [], 'description': '', 'filter': 'none', 'version': 'v4', 'network_id': '62643d65d2a98c05ccc7de24', 'name': ''}, {'allowed_sites': [], 'blocked_sites': [], 'blocked_tld': [], 'description': '', 'filter': 'none', 'version': 'v4', 'network_id': '5e42db1f7a5dae02b933555d', 'name': ''}, {'allowed_sites': [], 'blocked_sites': [], 'blocked_tld': [], 'description': '', 'filter': 'none', 'version': 'v4', 'network_id': '5f70f18b72dbef4dca8df269', 'name': ''}], 'honeypot': []}}
2022-11-19 21:17:23.783 ERROR (MainThread) [homeassistant.components.shell_command] Error running command: `bin/bash pushupdates.sh`, return code: 127
NoneType: None
2022-11-19 21:17:57.002 INFO (MainThread) [backoff] Backing off async_request(...) for 0.2s (tesla_wall_connector.exceptions.WallConnectorConnectionTimeoutError: Timeout while connecting to Wall Connector at 10.1.20.4)
2022-11-19 21:18:58.001 INFO (MainThread) [backoff] Backing off async_request(...) for 0.8s (tesla_wall_connector.exceptions.WallConnectorConnectionTimeoutError: Timeout while connecting to Wall Connector at 10.1.20.4)
2022-11-19 21:19:44.644 ERROR (MainThread) [homeassistant] Error doing job: Task exception was never retrieved
Traceback (most recent call last):
  File "/usr/local/lib/python3.10/site-packages/zwave_js_server/client.py", line 116, in async_send_command
    return await future
asyncio.exceptions.CancelledError

During handling of the above exception, another exception occurred:

Traceback (most recent call last):
  File "/usr/local/lib/python3.10/site-packages/zwave_js_server/model/node/__init__.py", line 574, in async_ping
    await self.async_send_command(
  File "/usr/local/lib/python3.10/site-packages/zwave_js_server/model/node/__init__.py", line 430, in async_send_command
    result = await self.client.async_send_command(message, **kwargs)
  File "/usr/local/lib/python3.10/site-packages/zwave_js_server/client.py", line 118, in async_send_command
    self._result_futures.pop(message_id)
KeyError: '19ef175c4ed247db9848cb8fc74ebf53'
