2022-11-19 21:43:41.360 WARNING (SyncWorker_0) [homeassistant.loader] We found a custom integration unifigateway which has not been tested by Home Assistant. This component might cause stability problems, be sure to disable it if you experience issues with Home Assistant
2022-11-19 21:43:41.361 WARNING (SyncWorker_0) [homeassistant.loader] We found a custom integration xiaomi_cloud_map_extractor which has not been tested by Home Assistant. This component might cause stability problems, be sure to disable it if you experience issues with Home Assistant
2022-11-19 21:43:41.361 WARNING (SyncWorker_0) [homeassistant.loader] We found a custom integration smartthinq_sensors which has not been tested by Home Assistant. This component might cause stability problems, be sure to disable it if you experience issues with Home Assistant
2022-11-19 21:43:41.362 WARNING (SyncWorker_0) [homeassistant.loader] We found a custom integration nodered which has not been tested by Home Assistant. This component might cause stability problems, be sure to disable it if you experience issues with Home Assistant
2022-11-19 21:43:41.362 WARNING (SyncWorker_0) [homeassistant.loader] We found a custom integration hacs which has not been tested by Home Assistant. This component might cause stability problems, be sure to disable it if you experience issues with Home Assistant
2022-11-19 21:43:41.362 WARNING (SyncWorker_0) [homeassistant.loader] We found a custom integration xiaomi_miot which has not been tested by Home Assistant. This component might cause stability problems, be sure to disable it if you experience issues with Home Assistant
2022-11-19 21:43:41.362 WARNING (SyncWorker_0) [homeassistant.loader] We found a custom integration tesla_custom which has not been tested by Home Assistant. This component might cause stability problems, be sure to disable it if you experience issues with Home Assistant
2022-11-19 21:43:43.873 INFO (MainThread) [backoff] Backing off async_request(...) for 0.1s (tesla_wall_connector.exceptions.WallConnectorConnectionTimeoutError: Timeout while connecting to Wall Connector at 10.1.20.4)
2022-11-19 21:43:44.043 WARNING (SyncWorker_6) [homeassistant.util.yaml.loader] YAML file /config/includes/main.yaml contains duplicate key "type". Check lines 786 and 787
2022-11-19 21:43:45.292 WARNING (MainThread) [homeassistant.components.unifiprotect.migrate] Failed to migate 1 reboot buttons
2022-11-19 21:43:45.582 WARNING (MainThread) [homeassistant.components.unifiprotect.migrate] Failed to migrate 24 entities
2022-11-19 21:43:46.253 WARNING (MainThread) [custom_components.xiaomi_miot] None device in xiaomi cloud: newlon@outlook.com
2022-11-19 21:43:47.959 WARNING (MainThread) [homeassistant.config_entries] Config entry 'Roku-Office' for roku integration not ready yet: Invalid response from API: Error occurred while communicating with device; Retrying in background
2022-11-19 21:43:48.458 WARNING (MainThread) [aioesphomeapi.reconnect_logic] Can't connect to ESPHome API for powermeter-18c @ 10.1.30.71: Error connecting to ('10.1.30.71', 6053): [Errno 113] Connect call failed ('10.1.30.71', 6053)
2022-11-19 21:43:54.202 WARNING (MainThread) [zigpy_znp.zigbee.application] Your network is using the insecure Zigbee2MQTT network key!
2022-11-19 21:43:55.320 WARNING (MainThread) [homeassistant.components.sonos.switch] Migration of Speech Enhancement switches on Living Room failed, manual cleanup required: ['switch.sonos_living_room_speech_enhancement', 'switch.sonos_living_room_speech_enhancement_2']
2022-11-19 21:44:02.793 WARNING (MainThread) [homeassistant.helpers.service] Unable to find referenced entities switch.off_24vac_all or it is/they are currently not available
2022-11-19 21:44:16.002 INFO (MainThread) [backoff] Backing off async_request(...) for 0.7s (tesla_wall_connector.exceptions.WallConnectorConnectionTimeoutError: Timeout while connecting to Wall Connector at 10.1.20.4)
2022-11-19 21:44:17.667 INFO (MainThread) [backoff] Backing off async_request(...) for 2.0s (tesla_wall_connector.exceptions.WallConnectorConnectionTimeoutError: Timeout while connecting to Wall Connector at 10.1.20.4)
2022-11-19 21:45:17.948 WARNING (MainThread) [homeassistant.components.zwave_js.services] This service is deprecated in favor of the ping button entity. Service calls will still work for now but the service will be removed in a future release
2022-11-19 21:45:17.949 WARNING (MainThread) [homeassistant.components.zwave_js.services] This service is deprecated in favor of the ping button entity. Service calls will still work for now but the service will be removed in a future release
2022-11-19 21:45:17.949 WARNING (MainThread) [homeassistant.components.zwave_js.services] This service is deprecated in favor of the ping button entity. Service calls will still work for now but the service will be removed in a future release
2022-11-19 21:45:17.950 WARNING (MainThread) [homeassistant.components.zwave_js.services] This service is deprecated in favor of the ping button entity. Service calls will still work for now but the service will be removed in a future release
2022-11-19 21:45:17.951 ERROR (MainThread) [homeassistant.components.websocket_api.http.connection] [23111629202208] 
Traceback (most recent call last):
  File "/usr/src/homeassistant/homeassistant/components/websocket_api/commands.py", line 200, in handle_call_service
    await hass.services.async_call(
  File "/usr/src/homeassistant/homeassistant/core.py", line 1744, in async_call
    task.result()
  File "/usr/src/homeassistant/homeassistant/core.py", line 1781, in _execute_service
    await cast(Callable[[ServiceCall], Awaitable[None]], handler.job.target)(
  File "/usr/src/homeassistant/homeassistant/components/zwave_js/services.py", line 625, in async_ping
    await asyncio.gather(*(node.async_ping() for node in nodes))
  File "/usr/local/lib/python3.10/site-packages/zwave_js_server/model/node/__init__.py", line 574, in async_ping
    await self.async_send_command(
  File "/usr/local/lib/python3.10/site-packages/zwave_js_server/model/node/__init__.py", line 430, in async_send_command
    result = await self.client.async_send_command(message, **kwargs)
  File "/usr/local/lib/python3.10/site-packages/zwave_js_server/client.py", line 114, in async_send_command
    await self._send_json_message(message)
  File "/usr/local/lib/python3.10/site-packages/zwave_js_server/client.py", line 420, in _send_json_message
    raise NotConnected
zwave_js_server.exceptions.NotConnected
2022-11-19 21:45:17.952 ERROR (MainThread) [homeassistant.components.websocket_api.http.connection] [23111629202208] '5b722eebe9f944668421128cd3bc7b7b'
Traceback (most recent call last):
  File "/usr/local/lib/python3.10/site-packages/zwave_js_server/client.py", line 116, in async_send_command
    return await future
asyncio.exceptions.CancelledError

During handling of the above exception, another exception occurred:

Traceback (most recent call last):
  File "/usr/src/homeassistant/homeassistant/components/websocket_api/commands.py", line 200, in handle_call_service
    await hass.services.async_call(
  File "/usr/src/homeassistant/homeassistant/core.py", line 1744, in async_call
    task.result()
  File "/usr/src/homeassistant/homeassistant/core.py", line 1781, in _execute_service
    await cast(Callable[[ServiceCall], Awaitable[None]], handler.job.target)(
  File "/usr/src/homeassistant/homeassistant/components/zwave_js/services.py", line 625, in async_ping
    await asyncio.gather(*(node.async_ping() for node in nodes))
  File "/usr/local/lib/python3.10/site-packages/zwave_js_server/model/node/__init__.py", line 574, in async_ping
    await self.async_send_command(
  File "/usr/local/lib/python3.10/site-packages/zwave_js_server/model/node/__init__.py", line 430, in async_send_command
    result = await self.client.async_send_command(message, **kwargs)
  File "/usr/local/lib/python3.10/site-packages/zwave_js_server/client.py", line 118, in async_send_command
    self._result_futures.pop(message_id)
KeyError: '5b722eebe9f944668421128cd3bc7b7b'
2022-11-19 21:45:17.953 ERROR (MainThread) [homeassistant.components.websocket_api.http.connection] [23111629202208] '9b1af9dc6074410497415f5aa84b8b09'
Traceback (most recent call last):
  File "/usr/local/lib/python3.10/site-packages/zwave_js_server/client.py", line 116, in async_send_command
    return await future
asyncio.exceptions.CancelledError

During handling of the above exception, another exception occurred:

Traceback (most recent call last):
  File "/usr/src/homeassistant/homeassistant/components/websocket_api/commands.py", line 200, in handle_call_service
    await hass.services.async_call(
  File "/usr/src/homeassistant/homeassistant/core.py", line 1744, in async_call
    task.result()
  File "/usr/src/homeassistant/homeassistant/core.py", line 1781, in _execute_service
    await cast(Callable[[ServiceCall], Awaitable[None]], handler.job.target)(
  File "/usr/src/homeassistant/homeassistant/components/zwave_js/services.py", line 625, in async_ping
    await asyncio.gather(*(node.async_ping() for node in nodes))
  File "/usr/local/lib/python3.10/site-packages/zwave_js_server/model/node/__init__.py", line 574, in async_ping
    await self.async_send_command(
  File "/usr/local/lib/python3.10/site-packages/zwave_js_server/model/node/__init__.py", line 430, in async_send_command
    result = await self.client.async_send_command(message, **kwargs)
  File "/usr/local/lib/python3.10/site-packages/zwave_js_server/client.py", line 118, in async_send_command
    self._result_futures.pop(message_id)
KeyError: '9b1af9dc6074410497415f5aa84b8b09'
2022-11-19 21:45:17.953 ERROR (MainThread) [homeassistant.components.websocket_api.http.connection] [23111629202208] '3a1a10d189bb40d78b20aed8ec1d4dce'
Traceback (most recent call last):
  File "/usr/local/lib/python3.10/site-packages/zwave_js_server/client.py", line 116, in async_send_command
    return await future
asyncio.exceptions.CancelledError

During handling of the above exception, another exception occurred:

Traceback (most recent call last):
  File "/usr/src/homeassistant/homeassistant/components/websocket_api/commands.py", line 200, in handle_call_service
    await hass.services.async_call(
  File "/usr/src/homeassistant/homeassistant/core.py", line 1744, in async_call
    task.result()
  File "/usr/src/homeassistant/homeassistant/core.py", line 1781, in _execute_service
    await cast(Callable[[ServiceCall], Awaitable[None]], handler.job.target)(
  File "/usr/src/homeassistant/homeassistant/components/zwave_js/services.py", line 625, in async_ping
    await asyncio.gather(*(node.async_ping() for node in nodes))
  File "/usr/local/lib/python3.10/site-packages/zwave_js_server/model/node/__init__.py", line 574, in async_ping
    await self.async_send_command(
  File "/usr/local/lib/python3.10/site-packages/zwave_js_server/model/node/__init__.py", line 430, in async_send_command
    result = await self.client.async_send_command(message, **kwargs)
  File "/usr/local/lib/python3.10/site-packages/zwave_js_server/client.py", line 118, in async_send_command
    self._result_futures.pop(message_id)
KeyError: '3a1a10d189bb40d78b20aed8ec1d4dce'
2022-11-19 21:45:17.990 WARNING (MainThread) [homeassistant.components.zwave_js.services] Driver is not ready.
2022-11-19 21:45:18.008 WARNING (MainThread) [homeassistant.components.zwave_js.services] Driver is not ready.
2022-11-19 21:45:18.029 WARNING (MainThread) [homeassistant.components.zwave_js.services] Driver is not ready.
2022-11-19 21:45:18.045 WARNING (MainThread) [homeassistant.components.zwave_js.services] Driver is not ready.
2022-11-19 21:45:18.056 WARNING (MainThread) [homeassistant.components.zwave_js.services] Driver is not ready.
2022-11-19 21:45:18.067 WARNING (MainThread) [homeassistant.components.zwave_js.services] Driver is not ready.
2022-11-19 21:45:18.358 WARNING (MainThread) [homeassistant.components.zwave_js.services] Driver is not ready.
2022-11-19 21:45:18.368 WARNING (MainThread) [homeassistant.components.zwave_js.services] Driver is not ready.
2022-11-19 21:45:18.368 WARNING (MainThread) [homeassistant.components.zwave_js.services] Driver is not ready.
2022-11-19 21:47:46.183 WARNING (MainThread) [homeassistant.helpers.service] Unable to find referenced entities switch.master_bedroom_closet_light, switch.porch_outlet or it is/they are currently not available
2022-11-19 21:48:13.087 WARNING (MainThread) [homeassistant.helpers.service] Unable to find referenced entities switch.master_bedroom_closet_light, switch.porch_outlet or it is/they are currently not available
2022-11-19 21:48:20.146 INFO (MainThread) [backoff] Backing off async_request(...) for 0.3s (tesla_wall_connector.exceptions.WallConnectorConnectionTimeoutError: Timeout while connecting to Wall Connector at 10.1.20.4)
